2024-07-16 16:12:59,221 INFO    StreamThr :1681710 [internal.py:wandb_internal():85] W&B internal server running at pid: 1681710, started at: 2024-07-16 16:12:59.219831
2024-07-16 16:12:59,228 DEBUG   HandlerThread:1681710 [handler.py:handle_request():158] handle_request: status
2024-07-16 16:12:59,229 INFO    WriterThread:1681710 [datastore.py:open_for_write():87] open: /lustre/home/ka/ka_ipc/ka_he8978/MACE_QEq_development/water_will/wandb/run-20240716_161259-nsk1umes/run-nsk1umes.wandb
2024-07-16 16:12:59,230 DEBUG   SenderThread:1681710 [sender.py:send():379] send: header
2024-07-16 16:12:59,230 DEBUG   SenderThread:1681710 [sender.py:send():379] send: run
2024-07-16 16:12:59,529 ERROR   SenderThread:1681710 [internal_api.py:execute():349] 400 response executing GraphQL.
2024-07-16 16:12:59,529 ERROR   SenderThread:1681710 [internal_api.py:execute():350] {"errors":[{"message":"you may not log runs directly to your organization, please try using your team entity","path":["upsertBucket"]}],"data":{"upsertBucket":null}}
2024-07-16 16:12:59,529 ERROR   SenderThread:1681710 [sender.py:send_run():1009] you may not log runs directly to your organization, please try using your team entity (Error 400: Bad Request)
Traceback (most recent call last):
  File "/lustre/home/ka/ka_ipc/ka_he8978/miniconda3/envs/mace_env/lib/python3.12/site-packages/wandb/apis/normalize.py", line 41, in wrapper
    return func(*args, **kwargs)
           ^^^^^^^^^^^^^^^^^^^^^
  File "/lustre/home/ka/ka_ipc/ka_he8978/miniconda3/envs/mace_env/lib/python3.12/site-packages/wandb/sdk/internal/internal_api.py", line 2224, in upsert_run
    response = self.gql(
               ^^^^^^^^^
  File "/lustre/home/ka/ka_ipc/ka_he8978/miniconda3/envs/mace_env/lib/python3.12/site-packages/wandb/sdk/internal/internal_api.py", line 317, in gql
    ret = self._retry_gql(
          ^^^^^^^^^^^^^^^^
  File "/lustre/home/ka/ka_ipc/ka_he8978/miniconda3/envs/mace_env/lib/python3.12/site-packages/wandb/sdk/lib/retry.py", line 131, in __call__
    result = self._call_fn(*args, **kwargs)
             ^^^^^^^^^^^^^^^^^^^^^^^^^^^^^^
  File "/lustre/home/ka/ka_ipc/ka_he8978/miniconda3/envs/mace_env/lib/python3.12/site-packages/wandb/sdk/internal/internal_api.py", line 345, in execute
    return self.client.execute(*args, **kwargs)  # type: ignore
           ^^^^^^^^^^^^^^^^^^^^^^^^^^^^^^^^^^^^
  File "/lustre/home/ka/ka_ipc/ka_he8978/miniconda3/envs/mace_env/lib/python3.12/site-packages/wandb/vendor/gql-0.2.0/wandb_gql/client.py", line 52, in execute
    result = self._get_result(document, *args, **kwargs)
             ^^^^^^^^^^^^^^^^^^^^^^^^^^^^^^^^^^^^^^^^^^^
  File "/lustre/home/ka/ka_ipc/ka_he8978/miniconda3/envs/mace_env/lib/python3.12/site-packages/wandb/vendor/gql-0.2.0/wandb_gql/client.py", line 60, in _get_result
    return self.transport.execute(document, *args, **kwargs)
           ^^^^^^^^^^^^^^^^^^^^^^^^^^^^^^^^^^^^^^^^^^^^^^^^^
  File "/lustre/home/ka/ka_ipc/ka_he8978/miniconda3/envs/mace_env/lib/python3.12/site-packages/wandb/sdk/lib/gql_request.py", line 59, in execute
    request.raise_for_status()
  File "/lustre/home/ka/ka_ipc/ka_he8978/miniconda3/envs/mace_env/lib/python3.12/site-packages/requests/models.py", line 1024, in raise_for_status
    raise HTTPError(http_error_msg, response=self)
requests.exceptions.HTTPError: 400 Client Error: Bad Request for url: https://api.wandb.ai/graphql

During handling of the above exception, another exception occurred:

Traceback (most recent call last):
  File "/lustre/home/ka/ka_ipc/ka_he8978/miniconda3/envs/mace_env/lib/python3.12/site-packages/wandb/sdk/internal/sender.py", line 1007, in send_run
    server_run = self._init_run(run, config_value_dict)
                 ^^^^^^^^^^^^^^^^^^^^^^^^^^^^^^^^^^^^^^
  File "/lustre/home/ka/ka_ipc/ka_he8978/miniconda3/envs/mace_env/lib/python3.12/site-packages/wandb/sdk/internal/sender.py", line 1079, in _init_run
    server_run, inserted, server_messages = self._api.upsert_run(
                                            ^^^^^^^^^^^^^^^^^^^^^
  File "/lustre/home/ka/ka_ipc/ka_he8978/miniconda3/envs/mace_env/lib/python3.12/site-packages/wandb/apis/normalize.py", line 51, in wrapper
    raise CommError(message, error)
wandb.errors.CommError: you may not log runs directly to your organization, please try using your team entity (Error 400: Bad Request)
2024-07-16 16:12:59,613 DEBUG   HandlerThread:1681710 [handler.py:handle_request():158] handle_request: shutdown
2024-07-16 16:12:59,613 INFO    HandlerThread:1681710 [handler.py:finish():882] shutting down handler
2024-07-16 16:13:00,230 INFO    WriterThread:1681710 [datastore.py:close():296] close: /lustre/home/ka/ka_ipc/ka_he8978/MACE_QEq_development/water_will/wandb/run-20240716_161259-nsk1umes/run-nsk1umes.wandb
2024-07-16 16:13:00,535 INFO    SenderThread:1681710 [sender.py:finish():1608] shutting down sender
